Workbook

Sheet README
AX7: Old Mindmap…replace with corrections

Sheet Inputs
A1: Inputs – Current State Baseline
A2: Customer-provided inputs used to derive current-state costs
A3: Client Name | B3: Acme
A4: Assessment Date (mm/dd/yyyy) | B4: 46052
A5: Customer Champion | B5: Guy Incognito
A6: XenTegra Engineer | B6: Stuart Donnelson
A7: Environment Basics
A8: User Count | B8: 2000
A9: Laptop Count | B9: 1500
A10: Desktop Count | B10: 200
A11: Thin Client Count | B11: 500
A13: Category Roll-Ups (Annual USD)
A14: End-User Devices
A15: Support & Operations
A16: Licensing
A17: Management & Security
A18: VDI / DaaS / Virtualization | B18: 256000
A19: Other / Overhead
A21: VDI / DaaS Detail (used for subset analytics not costs)
A22: VDI Users Present? | B22: Yes
A23: % of Users Using VDI | B23: 0.75
A24: Notes (optional) | B24: Using Citrix on-premises

Sheet Assumptions
A1: Assumptions – Defaults
A2: Default assumptions used when customer data is not provided | B2: Default Value | C2: Notes
A3: Laptop Refresh Cycle (Years) | B3: 3 | C3: Editable per engagement
A4: Desktop Refresh Cycle (Years) | B4: 3 | C4: Editable per engagement
A5: Thin Client Refresh Cycle (Years) | B5: 5 | C5: Editable per engagement
A6: Avg Ticket Handling Time (Hours) | B6: 0.5 | C6: Used for Support & Ops derivation
A7: Deployment / Imaging Hours per Device | B7: 1.5 | C7: Used for Support & Ops derivation
A8: Blended IT Labor Rate (Hourly USD) | B8: 50 | C8: Used for Support & Ops derivation
A9: Tickets per Endpoint per Year | B9: 2 | C9: Used for Support & Ops derivation
A10: Overhead % of Total Baseline Costs | B10: 0.07 | C10: Applied to subtotal if overhead rollup missing
A11: Laptop Unit Cost (USD) | B11: 1200 | C11: Used for device derivation
A12: Desktop Unit Cost (USD) | B12: 1100 | C12: Used for device derivation
A13: Thin Client Unit Cost (USD) | B13: 600 | C13: Used for device derivation
A14: Licensing Avg Cost per User (USD/Year) | B14: 400 | C14: End-user software only
... A17: VDI Platform Cost per VDI User (USD/Year) | B17: 800 | C17: Used if VDI rollup missing

Sheet Observations_Analysis
A1: Observations & Analysis
A3: Present? | B3: Observation | C3: Source
A4: Yes | B4: This assessment includes managed corporate endpoints only (laptops, desktops, and thin clients) and excludes mobile devices, BYOD, shared/kiosk devices, and VDI-only users without corporate endpoints. | C4: Scope
A5: =IF(Inputs!B14<>"","No","Yes") -> Yes | B5: End-user device costs were derived using assumed unit costs and refresh cycles by device type, as customer-provided roll-up values were not available. | C5: End-User Devices
A6: =IF(Inputs!B15<>"","No","Yes") -> Yes | B6: Support and operations costs were estimated using assumed ticket volumes, handling time, and a blended labor rate, in the absence of customer-provided annual support cost data. | C6: Support & Operations
A7: =IF(Inputs!B16<>"","No","Yes") -> Yes | B7: Licensing costs were derived using assumed per-user licensing costs and coverage percentages, as customer-provided licensing totals were not available. | C7: Licensing
A8: =IF(Inputs!B17<>"","No","Yes") -> Yes | B8: Management and security tooling costs were estimated using assumed per-user or per-endpoint values due to the absence of customer-provided cost data. | C8: Mgmt & Security
A9: =IF(OR(Inputs!B18<>"",_Calc!B10>0),"Yes","No") -> Yes | B9: A subset of users were identified as VDI users; associated VDI platform costs were included based on customer-provided or assumed values. | C9: VDI / DaaS
A10: =IF(AND(Inputs!B18="",_Calc!B10>0),"Yes","No") -> No | B10: VDI platform costs were estimated using assumed values due to the absence of customer-provided annual VDI cost data. | C10: VDI / DaaS
A11: =IF(Inputs!B19<>"","No","Yes") -> Yes | B11: Overhead costs were derived as a percentage of total baseline costs, as customer-provided overhead allocations were not available. | C11: Overhead
A12: =IF((IF(_Calc!D32<>1,1,0)+IF(_Calc!D33<>1,1,0)+IF(_Calc!D34<>1,1,0)+IF(_Calc!D35<>1,1,0)+IF(_Calc!D36<>1,1,0)+IF(_Calc!D37<>1,1,0))>=3,"Yes","No") -> Yes | B12: Multiple cost categories in this assessment were derived using assumptions due to limited availability of customer-provided cost data. | C12: Global

Sheet Informational_Inputs
A1: Informational / Contextual Inputs (Non‑Cost)
A2: Environmental context and tooling presence (non-cost)
A3: VDI / DaaS Platform Presence
A4: Platform | B4: Present? | C4: Notes
A5: Citrix | B5: Yes | C5: Citrix LTSR version 2507
A6: Azure Virtual Desktop | B6: No
A7: Windows 365 | B7: Yes | C7: Windows 365
A8: Horizon | B8: No
A9: Parallels | B9: No
A11: Endpoint & Management Tools
A12: Tool | B12: Present? | C12: Notes
A13: Intune | B13: Unknown
A14: SCCM | B14: Unknown
A15: Workspace ONE | B15: Unknown
A16: Jamf | B16: Unknown
A17: ControlUp | B17: Unknown
A18: Nerdio | B18: Unknown
A21: Derived Indicators
A22: Cloud‑Hosted EUC Presence | B22: =IF(OR(B6="Yes",B7="Yes"),"Present","Not Identified") -> Present | C22: Derived from AVD or Windows 365 presence

Sheet Summary
A1: Summary – Current-State Baseline
A3: Total Annual Cost | B3: =_Calc!B41 -> 2556586.7
A4: Cost per User (Annual) | B4: =_Calc!B42 -> 1278.2933
A6: Category | B6: Annual Cost | C6: Source | D6: Source Detail
A7: End-User Devices | B7: =_Calc!B32 -> 733333.33 | C7: =_Calc!C32 -> Derived | D7: =_Calc!E32 -> Derived from device counts + assumptions
A8: Support & Operations | B8: =_Calc!B33 -> 160000 | C8: =_Calc!C33 -> Derived | D8: =_Calc!E33 -> Derived from endpoint counts + assumptions
A9: Licensing | B9: =_Calc!B34 -> 800000 | C9: =_Calc!C34 -> Derived | D9: =_Calc!E34 -> Derived from user count + assumptions
A10: Management & Security | B10: =_Calc!B35 -> 440000 | C10: =_Calc!C35 -> Derived | D10: =_Calc!E35 -> Derived from endpoint counts + assumptions
A11: VDI / DaaS / Virtualization | B11: =_Calc!B36 -> 256000 | C11: =_Calc!C36 -> Input | D11: =_Calc!E36 -> Customer roll-up provided
A12: Other / Overhead | B12: =_Calc!B37 -> 167253.33 | C12: =_Calc!C37 -> Derived | D12: =_Calc!E37 -> Derived as % of subtotal (assumption-driven)
A15: VDI Incremental View (if applicable)
A16: Non-VDI User Cost (Annual) | B16: =_Calc!B47 -> 1150.2933
A17: VDI User Cost (Annual) | B17: =_Calc!B48 -> 1320.96
A18: VDI Cost per VDI User (Annual) | B18: =_Calc!B45 -> 170.66667

Sheet Executive_PDF
A1: Current-State Cost Baseline — Executive Summary
A3: Total Annual Cost | B3: =Summary!B3 -> 2556586.7
A4: Cost per User (Annual) | B4: =Summary!B4 -> 1278.2933
A6: Category | B6: Annual Cost
A7: End-User Devices | B7: =Summary!B7 -> 733333.33
A8: Support & Operations | B8: =Summary!B8 -> 160000
A9: Licensing | B9: =Summary!B9 -> 800000
A10: Management & Security | B10: =Summary!B10 -> 440000
A11: VDI / DaaS / Virtualization | B11: =Summary!B11 -> 256000
A12: Other / Overhead | B12: =Summary!B12 -> 167253.33
A15: VDI Incremental View
A16: Non-VDI User Cost (Annual) | B16: =Summary!B16 -> 1150.2933
A17: VDI User Cost (Annual) | B17: =Summary!B17 -> 1320.96
A18: VDI Cost per VDI User (Annual) | B18: =Summary!B18 -> 170.66667
A22: Cost Breakdown by Category
A23: End-User Devices | B23: =Summary!B7 -> 733333.33
A24: Support & Operations | B24: =Summary!B8 -> 160000
A25: Licensing | B25: =Summary!B9 -> 800000
A26: Management & Security | B26: =Summary!B10 -> 440000
A27: VDI / DaaS / Virtualization | B27: =Summary!B11 -> 256000
A28: Other / Overhead | B28: =Summary!B12 -> 167253.33
A31: Cost Source Confidence
A32: Source | B32: Annual Cost
A33: Derived | B33: =SUMIF(_Calc!$C$32:$C$37,"Derived",_Calc!$B$32:$B$37) -> 2300586.7
A34: Assumption | B34: =SUMIF(_Calc!$C$32:$C$37,"Assumption",_Calc!$B$32:$B$37) -> 0

Sheet Appendix_Visuals
A1: Appendix — Supporting Visuals
A3: Endpoint Mix
A4: Device Type | B4: Count
A5: Laptops | B5: =_Calc!B4 -> 1500
A6: Desktops | B6: =_Calc!B5 -> 200
A7: Thin Clients | B7: =_Calc!B6 -> 500
A8: Total | B8: =SUM(B5:B7) -> 2200
A12: Cost per User by Category
A13: Category | B13: Cost per User
A14: End-User Devices | B14: =IF(_Calc!B3>0,Summary!B7/_Calc!B3,"") -> 366.66667
A15: Support & Operations | B15: =IF(_Calc!B3>0,Summary!B8/_Calc!B3,"") -> 80
A16: Licensing | B16: =IF(_Calc!B3>0,Summary!B9/_Calc!B3,"") -> 400
A17: Management & Security | B17: =IF(_Calc!B3>0,Summary!B10/_Calc!B3,"") -> 220
A18: VDI / DaaS / Virtualization | B18: =IF(_Calc!B3>0,Summary!B11/_Calc!B3,"") -> 128
A19: Other / Overhead | B19: =IF(_Calc!B3>0,Summary!B12/_Calc!B3,"") -> 83.626667
A23: Informational Context (Non‑Cost)
A25: VDI / DaaS Platform Footprint
A26: Platform | B26: Present? | C26: Notes
A27: Citrix | B27: =Informational_Inputs!B5 -> Yes | C27: =Informational_Inputs!C5 -> Citrix LTSR version 2507
A28: Azure Virtual Desktop | B28: =Informational_Inputs!B6 -> No | C28: =Informational_Inputs!C6 -> 0
A29: Windows 365 | B29: =Informational_Inputs!B7 -> Yes | C29: =Informational_Inputs!C7 -> Windows 365
A30: Horizon | B30: =Informational_Inputs!B8 -> No | C30: =Informational_Inputs!C8 -> 0
A31: Parallels | B31: =Informational_Inputs!B9 -> No | C31: =Informational_Inputs!C9 -> 0
A34: Management Tool Landscape
A35: Tool | B35: Present? | C35: Notes
A36: Intune | B36: =Informational_Inputs!B13 -> Unknown | C36: =Informational_Inputs!C13 -> 0
A37: SCCM | B37: =Informational_Inputs!B14 -> Unknown | C37: =Informational_Inputs!C14 -> 0
A38: Workspace ONE | B38: =Informational_Inputs!B15 -> Unknown | C38: =Informational_Inputs!C15 -> 0
A39: Jamf | B39: =Informational_Inputs!B16 -> Unknown | C39: =Informational_Inputs!C16 -> 0
A40: ControlUp | B40: =Informational_Inputs!B17 -> Unknown | C40: =Informational_Inputs!C17 -> 0
A41: Nerdio | B41: =Informational_Inputs!B18 -> Unknown | C41: =Informational_Inputs!C18 -> 0
A44: Cloud EUC Presence Indicator
A45: Status | B45: =Informational_Inputs!B22 -> Present | C45: Derived - AVD or Win365 usage

Sheet _Calc
A1: _Calc – Engine (Do not edit)
A2: Metric | B2: Value | C2: Value Source | D2: Source Code | E2: Source Detail
A3: User_Count | B3: =Inputs!B8 -> 2000 | C3: Input
A4: Laptop_Count | B4: =Inputs!B9 -> 1500 | C4: Input
A5: Desktop_Count | B5: =Inputs!B10 -> 200 | C5: Input
A6: ThinClient_Count | B6: =Inputs!B11 -> 500 | C6: Input
A7: Endpoint_Count | B7: =SUM(B4:B6) -> 2200 | C7: Derived
A8: VDI_Present | B8: =Inputs!B22 -> Yes | C8: Input
A9: VDI_Pct | B9: =Inputs!B23 -> 0.75 | C9: Input
A10: VDI_User_Count | B10: =IFERROR(B3*B9,0) -> 1500 | C10: Derived
A13: Assumptions (fixed references)
A14: Assumption | B14: Value | C14: Ref
A15: Laptop Refresh Cycle (Years) | B15: =Assumptions!B3 -> 3 | C15: Assumptions!B3
A16: Desktop Refresh Cycle (Years) | B16: =Assumptions!B4 -> 3 | C16: Assumptions!B4
A17: Thin Client Refresh Cycle (Years) | B17: =Assumptions!B5 -> 5 | C17: Assumptions!B5
A18: Laptop Unit Cost (USD) | B18: =Assumptions!B11 -> 1200 | C18: Assumptions!B11
A19: Desktop Unit Cost (USD) | B19: =Assumptions!B12 -> 1100 | C19: Assumptions!B12
A20: Thin Client Unit Cost (USD) | B20: =Assumptions!B13 -> 600 | C20: Assumptions!B13
A21: Tickets per Endpoint per Year | B21: =Assumptions!B9 -> 2 | C21: Assumptions!B9
A22: Avg Ticket Handling Time (Hours) | B22: =Assumptions!B6 -> 0.5 | C22: Assumptions!B6
A23: Deployment / Imaging Hours per Device | B23: =Assumptions!B7 -> 1.5 | C23: Assumptions!B7
A24: Blended IT Labor Rate (Hourly USD) | B24: =Assumptions!B8 -> 50 | C24: Assumptions!B8
A25: Licensing Avg Cost per User (USD/Year) | B25: =Assumptions!B14 -> 400 | C25: Assumptions!B14
A26: Licensing Coverage % | B26: =Assumptions!B15 -> 1 | C26: Assumptions!B15
A27: Mgmt & Security Cost per Endpoint (USD/Year) | B27: =Assumptions!B16 -> 200 | C27: Assumptions!B16
A28: VDI Platform Cost per VDI User (USD/Year) | B28: =Assumptions!B17 -> 800 | C28: Assumptions!B17
A29: Overhead % of Total Baseline Costs | B29: =Assumptions!B10 -> 0.07 | C29: Assumptions!B10
A31: Category | B31: Annual Cost | C31: Value Source
A32: End-User Devices | B32: =IF(Inputs!B14<>"",Inputs!B14,(B4*B18/B15+B5*B19/B16+B6*B20/B17)) -> 733333.33 | C32: =CHOOSE(D32,"Input","Derived","Assumption") -> Derived | D32: =IF(Inputs!B14<>"",1,IF((B4+B5+B6)>0,2,3)) -> 2 | E32: =IF(Inputs!B14<>"","Customer roll-up provided",IF((B4+B5+B6)>0,"Derived from device counts + assumptions","Assumptions only (missing device counts)")) -> Derived from device counts + assumptions
A33: Support & Operations | B33: =IF(Inputs!B15<>"",Inputs!B15,(B7*B21*B22*B24+(B4/B15+B5/B16+B6/B17)*B23*B24)) -> 160000 | C33: =CHOOSE(D33,"Input","Derived","Assumption") -> Derived | D33: =IF(Inputs!B15<>"",1,IF((B7>0),2,3)) -> 2 | E33: =IF(Inputs!B15<>"","Customer roll-up provided",IF((B7>0),"Derived from endpoint counts + assumptions","Assumptions only (missing endpoint counts)")) -> Derived from endpoint counts + assumptions
A34: Licensing | B34: =IF(Inputs!B16<>"",Inputs!B16,(B3*B25*B26)) -> 800000 | C34: =CHOOSE(D34,"Input","Derived","Assumption") -> Derived | D34: =IF(Inputs!B16<>"",1,IF((B3>0),2,3)) -> 2 | E34: =IF(Inputs!B16<>"","Customer roll-up provided",IF((B3>0),"Derived from user count + assumptions","Assumptions only (missing user count)")) -> Derived from user count + assumptions
A35: Management & Security | B35: =IF(Inputs!B17<>"",Inputs!B17,(B7*B27)) -> 440000 | C35: =CHOOSE(D35,"Input","Derived","Assumption") -> Derived | D35: =IF(Inputs!B17<>"",1,IF((B7>0),2,3)) -> 2 | E35: =IF(Inputs!B17<>"","Customer roll-up provided",IF((B7>0),"Derived from endpoint counts + assumptions","Assumptions only (missing endpoint counts)")) -> Derived from endpoint counts + assumptions
A36: VDI / DaaS / Virtualization | B36: =IF(Inputs!B18<>"",Inputs!B18,(B10*B28)) -> 256000 | C36: =CHOOSE(D36,"Input","Derived","Assumption") -> Input | D36: =IF(Inputs!B18<>"",1,IF((B10>0),2,3)) -> 1 | E36: =IF(Inputs!B18<>"","Customer roll-up provided",IF((B10>0),"Derived from VDI subset + assumptions","Assumptions only (no VDI subset)")) -> Customer roll-up provided
A37: Other / Overhead | B37: =IF(Inputs!B19<>"",Inputs!B19,(B29*(B32+B33+B34+B35+B36))) -> 167253.33 | C37: =CHOOSE(D37,"Input","Derived","Assumption") -> Derived | D37: =IF(Inputs!B19<>"",1,IF((SUM(B32:B36)>0),2,3)) -> 2 | E37: =IF(Inputs!B19<>"","Customer roll-up provided","Derived as % of subtotal (assumption-driven)") -> Derived as % of subtotal (assumption-driven)
A40: Totals
A41: Total Annual Cost | B41: =SUM(B32:B37) -> 2556586.7
A42: Cost per User (Annual) | B42: =IF(B3>0,B41/B3,"") -> 1278.2933
A44: VDI Analytics
A45: VDI Cost per VDI User | B45: =IF(B10>0,B36/B10,"") -> 170.66667
A46: Baseline Cost per User (Excl. VDI) | B46: =IF(B3>0,(B41-B36)/B3,"") -> 1150.2933
...

Sheet _Checks
A1: _Checks – Readiness (v0.6)
A3: Check | B3: Status | C3: Detail
A4: User Count provided | B4: =IF(_Calc!B3>0,"PASS","FAIL") -> PASS | C4: =_Calc!B3 -> 2000
A5: VDI % is valid (0–100%) | B5: =IF(AND(_Calc!B9>=0,_Calc!B9<=1),"PASS","FAIL") -> PASS | C5: =_Calc!B9 -> 0.75
A6: Endpoint counts not negative | B6: =IF(AND(_Calc!B4>=0,_Calc!B5>=0,_Calc!B6>=0),"PASS","FAIL") -> PASS | C6: ="L="&_Calc!B4&", D="&_Calc!B5&", T="&_Calc!B6 -> L=1500, D=200, T=500
A7: No negative category costs | B7: =IF(MIN(_Calc!B32:'_Calc'!B37)>=0,"PASS","FAIL") -> PASS | C7: =MIN(_Calc!B32:'_Calc'!B37) -> 160000
A8: Assumptions used (informational) | B8: =IF((IF(_Calc!D32<>1,1,0)+IF(_Calc!D33<>1,1,0)+IF(_Calc!D34<>1,1,0)+IF(_Calc!D35<>1,1,0)+IF(_Calc!D36<>1,1,0)+IF(_Calc!D37<>1,1,0))>0,"INFO","OK") -> INFO | C8: =(IF(_Calc!D32<>1,1,0)+IF(_Calc!D33<>1,1,0)+IF(_Calc!D34<>1,1,0)+IF(_Calc!D35<>1,1,0)+IF(_Calc!D36<>1,1,0)+IF(_Calc!D37<>1,1,0))&" categories not provided as roll-up inputs" -> 5 categories not provided as roll-up inputs

Sheet _Wiring
A1: Wire_ID | B1: Domain | C1: Node_Type | D1: Node_Name | E1: Sheet | F1: Cell_or_NamedRange | G1: Definition | H1: Formula_or_SourceLogic | I1: Upstream_Dependencies | J1: Downstream_Consumers | K1: Output_Surface | L1: Notes
A2: W-INP-001 | B2: Basics | C2: INP | D2: INP_User_Count | E2: Inputs | F2: B8 | G2: Total number of users | H2: Manual input | J2: CALC_User_Count, CALC_Licensing, CALC_VDI_User_Count, CALC_Cost_Per_User | K2: None
A3: W-INP-002 | B3: Devices | C3: INP | D3: INP_Laptop_Count | E3: Inputs | F3: B9 | G3: Count of laptops | H3: Manual input | J3: CALC_Laptop_Count, CALC_Endpoint_Count, CALC_EndUserDevices | K3: None
A4: W-INP-003 | B4: Devices | C4: INP | D4: INP_Desktop_Count | E4: Inputs | F4: B10 | G4: Count of desktops | H4: Manual input | J4: CALC_Desktop_Count, CALC_Endpoint_Count, CALC_EndUserDevices | K4: None
A5: W-INP-004 | B5: Devices | C5: INP | D5: INP_ThinClient_Count | E5: Inputs | F5: B11 | G5: Count of thin clients | H5: Manual input | J5: CALC_ThinClient_Count, CALC_Endpoint_Count, CALC_EndUserDevices | K5: None
A6: W-INP-010 | B6: Category Rollups | C6: INP | D6: INP_Rollup_EndUserDevices_Annual | E6: Inputs | F6: B14 | G6: Customer-provided annual cost roll-up for End-User Devices | H6: Manual input (optional) | J6: CALC_EndUserDevices | K6: None | L6: Overrides derived device lifecycle cost
A7: W-INP-011 | B7: Category Rollups | C7: INP | D7: INP_Rollup_SupportOps_Annual | E7: Inputs | F7: B15 | G7: Customer-provided annual cost roll-up for Support & Operations | H7: Manual input (optional) | J7: CALC_SupportOps | K7: None | L7: Overrides derived support cost
A8: W-INP-012 | B8: Category Rollups | C8: INP | D8: INP_Rollup_Licensing_Annual | E8: Inputs | F8: B16 | G8: Customer-provided annual cost roll-up for Licensing | H8: Manual input (optional) | J8: CALC_Licensing | K8: None | L8: Overrides derived licensing cost
A9: W-INP-013 | B9: Category Rollups | C9: INP | D9: INP_Rollup_MgmtSec_Annual | E9: Inputs | F9: B17 | G9: Customer-provided annual cost roll-up for Management & Security | H9: Manual input (optional) | J9: CALC_MgmtSec | K9: None | L9: Overrides derived mgmt & security cost
A10: W-INP-014 | B10: Category Rollups | C10: INP | D10: INP_Rollup_Virtualization_Annual | E10: Inputs | F10: B18 | G10: Customer-provided annual cost roll-up for VDI / DaaS / Virtualization | H10: Manual input (optional) | J10: CALC_Virtualization | K10: None | L10: Overrides derived virtualization cost
A11: W-INP-015 | B11: Category Rollups | C11: INP | D11: INP_Rollup_Overhead_Annual | E11: Inputs | F11: B19 | G11: Customer-provided annual cost roll-up for Other / Overhead | H11: Manual input (optional) | J11: CALC_Overhead | K11: None | L11: Overrides derived overhead cost
A12: W-INP-020 | B12: VDI Detail | C12: INP | D12: INP_VDI_Present | E12: Inputs | F12: B22 | G12: Whether VDI users are present (Yes/No) | H12: Manual input | J12: CALC_VDI_Present | K12: None | L12: Currently informational; not used in cost formula
A13: W-INP-021 | B13: VDI Detail | C13: INP | D13: INP_VDI_Pct | E13: Inputs | F13: B23 | G13: Percentage of users using VDI (0–1) | H13: Manual input | J13: CALC_VDI_Pct, CALC_VDI_User_Count | K13: None | L13: Used to estimate VDI subset
A14: W-INP-022 | B14: VDI Detail | C14: INP | D14: INP_VDI_Notes | E14: Inputs | F14: B24 | G14: Optional notes on VDI usage | H14: Manual input | J14: OUT_VDI_Notes | K14: None | L14: Displayed only (if surfaced)
A15: W-ASM-001 | B15: Assumptions | C15: ASM | D15: ASM_Laptop_Refresh_Yrs | E15: Assumptions | F15: B3 | G15: Laptop refresh cycle in years | H15: Assumption value | J15: CALC_* | K15: None
A16: W-ASM-002 | B16: Assumptions | C16: ASM | D16: ASM_Desktop_Refresh_Yrs | E16: Assumptions | F16: B4 | G16: Desktop refresh cycle in years | H16: Assumption value | J16: CALC_* | K16: None
A17: W-ASM-003 | B17: Assumptions | C17: ASM | D17: ASM_ThinClient_Refresh_Yrs | E17: Assumptions | F17: B5 | G17: Thin client refresh cycle in years | H17: Assumption value | J17: CALC_* | K17: None
A18: W-ASM-004 | B18: Assumptions | C18: ASM | D18: ASM_Avg_Ticket_Hours | E18: Assumptions | F18: B6 | G18: Average handling time per ticket in hours | H18: Assumption value | J18: CALC_* | K18: None
A19: W-ASM-005 | B19: Assumptions | C19: ASM | D19: ASM_Deploy_Hours_Per_Device | E19: Assumptions | F19: B7 | G19: Deployment/imaging hours per device | H19: Assumption value | J19: CALC_* | K19: None
A20: W-ASM-006 | B20: Assumptions | C20: ASM | D20: ASM_Blended_Labor_Rate | E20: Assumptions | F20: B8 | G20: Blended IT labor rate (hourly USD) | H20: Assumption value | J20: CALC_* | K20: None
A21: W-ASM-007 | B21: Assumptions | C21: ASM | D21: ASM_Tickets_Per_Endpoint | E21: Assumptions | F21: B9 | G21: Tickets per endpoint per year | H21: Assumption value | J21: CALC_* | K21: None
A22: W-ASM-008 | B22: Assumptions | C22: ASM | D22: ASM_Overhead_Pct | E22: Assumptions | F22: B10 | G22: Overhead percentage applied to subtotal | H22: Assumption value | J22: CALC_* | K22: None
A23: W-ASM-009 | B23: Assumptions | C23: ASM | D23: ASM_Laptop_Unit_Cost | E23: Assumptions | F23: B11 | G23: Laptop unit cost (USD) | H23: Assumption value | J23: CALC_* | K23: None
A24: W-ASM-010 | B24: Assumptions | C24: ASM | D24: ASM_Desktop_Unit_Cost | E24: Assumptions | F24: B12 | G24: Desktop unit cost (USD) | H24: Assumption value | J24: CALC_* | K24: None
A25: W-ASM-011 | B25: Assumptions | C25: ASM | D25: ASM_ThinClient_Unit_Cost | E25: Assumptions | F25: B13 | G25: Thin client unit cost (USD) | H25: Assumption value | J25: CALC_* | K25: None
A26: W-ASM-012 | B26: Assumptions | C26: ASM | D26: ASM_Lic_Cost_Per_User | E26: Assumptions | F26: B14 | G26: Average licensing cost per user per year | H26: Assumption value | J26: CALC_* | K26: None
... A29: W-ASM-015 | B29: Assumptions | C29: ASM | D29: ASM_VDI_Cost_Per_VDI_User | E29: Assumptions | F29: B17 | G29: VDI platform cost per VDI user per year | H29: Assumption value | J29: CALC_* | K29: None
A30: W-CALC-001 | B30: Calc Inputs | C30: CALC | D30: CALC_User_Count | E30: _Calc | F30: B3 | G30: User count value used by engine | H30: '=Inputs!B8 | I30: INP_User_Count | J30: CALC_Licensing, CALC_Cost_Per_User | K30: None
A31: W-CALC-002 | B31: Calc Inputs | C31: CALC | D31: CALC_Laptop_Count | E31: _Calc | F31: B4 | G31: Laptop count used by engine | H31: '=Inputs!B9 | I31: INP_Laptop_Count | J31: CALC_Endpoint_Count, CALC_EndUserDevices | K31: None
A32: W-CALC-003 | B32: Calc Inputs | C32: CALC | D32: CALC_Desktop_Count | E32: _Calc | F32: B5 | G32: Desktop count used by engine | H32: '=Inputs!B10 | I32: INP_Desktop_Count | J32: CALC_Endpoint_Count, CALC_EndUserDevices | K32: None
A33: W-CALC-004 | B33: Calc Inputs | C33: CALC | D33: CALC_ThinClient_Count | E33: _Calc | F33: B6 | G33: Thin client count used by engine | H33: '=Inputs!B11 | I33: INP_ThinClient_Count | J33: CALC_Endpoint_Count, CALC_EndUserDevices | K33: None
A34: W-CALC-005 | B34: Devices | C34: CALC | D34: CALC_Endpoint_Count | E34: _Calc | F34: B7 | G34: Total endpoints | H34: '=SUM(B4:B6) | I34: CALC_Laptop_Count,CALC_Desktop_Count,CALC_ThinClient_Count | J34: CALC_EndUserDevices, CALC_SupportOps, CALC_MgmtSec | K34: Summary, Exec_PDF
A35: W-CALC-006 | B35: VDI Detail | C35: CALC | D35: CALC_VDI_Present | E35: _Calc | F35: B8 | G35: VDI present indicator | H35: '=Inputs!B22 | I35: INP_VDI_Present | J35: (informational) | K35: None
A36: W-CALC-007 | B36: VDI Detail | C36: CALC | D36: CALC_VDI_Pct | E36: _Calc | F36: B9 | G36: VDI percent of users | H36: '=Inputs!B23 | I36: INP_VDI_Pct | J36: CALC_VDI_User_Count | K36: None
A37: W-CALC-008 | B37: VDI Detail | C37: CALC | D37: CALC_VDI_User_Count | E37: _Calc | F37: B10 | G37: Estimated VDI user count | H37: '=IFERROR(B3*B9,0) | I37: CALC_User_Count,CALC_VDI_Pct | J37: CALC_Virtualization | K37: None
A38: W-CALC-A15 | B38: Assumption Refs | C38: CALC | D38: CALC_Laptop_Refresh_Cycle_Years | E38: _Calc | F38: B15 | G38: Engine reference for assumption: Laptop Refresh Cycle (Years) | H38: '==Assumptions!B3 | J38: Multiple | K38: None | L38: Pass-through ref for stability
A39: W-CALC-A16 | B39: Assumption Refs | C39: CALC | D39: CALC_Desktop_Refresh_Cycle_Years | E39: _Calc | F39: B16 | G39: Engine reference for assumption: Desktop Refresh Cycle (Years) | H39: '==Assumptions!B4 | J39: Multiple | K39: None | L39: Pass-through ref for stability
A40: W-CALC-A17 | B40: Assumption Refs | C40: CALC | D40: CALC_Thin_Client_Refresh_Cycle_Years | E40: _Calc | F40: B17 | G40: Engine reference for assumption: Thin Client Refresh Cycle (Years) | H40: '==Assumptions!B5 | J40: Multiple | K40: None | L40: Pass-through ref for stability
A41: W-CALC-A18 | B41: Assumption Refs | C41: CALC | D41: CALC_Laptop_Unit_Cost_USD | E41: _Calc | F41: B18 | G41: Engine reference for assumption: Laptop Unit Cost (USD) | H41: '==Assumptions!B11 | J41: Multiple | K41: None | L41: Pass-through ref for stability
A42: W-CALC-A19 | B42: Assumption Refs | C42: CALC | D42: CALC_Desktop_Unit_Cost_USD | E42: _Calc | F42: B19 | G42: Engine reference for assumption: Desktop Unit Cost (USD) | H42: '==Assumptions!B12 | J42: Multiple | K42: None | L42: Pass-through ref for stability
...
